Workbook
Name _1_USD: #REF!
Name _1_USD: #REF!
Name _1_USD: #REF!
Name _1_USD: #REF!
Name _1_USD: #REF!
Name _1_USD: #REF!
Name _1_USD: #REF!
Name _1_USD: #REF!
Name _1_USD: #REF!
Name _1_USD: #REF!
Name _1_USD: #REF!
Name _1_USD: #REF!
Name _1_USD: #REF!
Name _1_USD: #REF!
Name _1_USD: #REF!
Name _1_USD: #REF!
Name _1_USD: #REF!
Name _1_USD: #REF!
Name _1_USD: #REF!
Name _1_USD: #REF!
Name _1_USD: #REF!
Name _1_USD: #REF!
Name _1_USD: #REF!
Name _1_USD: #REF!
Name _1_USD: #REF!
Name _1_USD: #REF!
Name _1_USD: #REF!
Name _1_USD: #REF!
Name _1_USD: #REF!
Name _1_USD: #REF!
Name _1_USD: #REF!
Name _1_USD: #REF!
Name _1_USD: #REF!
Name _1_USD: #REF!
Name _1_USD: #REF!
Name _1_USD: #REF!
Name _1_USD: #REF!
Name _1_USD: #REF!
Name _1_USD: #REF!
Name _1_USD: #REF!
Name _2_: #REF!
Name _2_: #REF!
Name _2_: #REF!
Name _2_: #REF!
Name _2_: #REF!
Name _2_: #REF!
Name _2_: #REF!
Name _2_: #REF!
Name _2_: #REF!
Name _2_: #REF!
Name _2_: #REF!
Name _2_: #REF!
Name _2_: #REF!
Name _2_: #REF!
Name _2_: #REF!
Name _2_: #REF!
Name _2_: #REF!
Name _2_: #REF!
Name _2_: #REF!
Name _2_: #REF!

Sheet титульный лист
A1: Государственная корпорация «Роскосмос»
A3: Сокращенное название организации | H3: Утверждаю
H4: Генеральный директор
H6: _________________ / _______________
H7: " _____" _______________ 2017 г.
A9: Производственно-технологический П А С П О Р Т
A10: организации государственной корпорации «Роскосмос»
A14: ________________________________________________________________________________
A15: (полное наименование и расположение организации)
G18: Главный инженер | H18: _________________/ _______________
H19: (подпись) (Ф.И.О.)
G20: Заместитель генерального директора по экономике и финансам | H20: _________________/ _______________
H21: (подпись) (Ф.И.О.)
G22: Заместитель генерального директора по персоналу | H22: _________________/ _______________
H23: (подпись) (Ф.И.О.)
G24: Главный технолог | H24: _________________/ _______________
H25: (подпись) (Ф.И.О.)
G26: Главный механик | H26: _________________/ _______________
H27: (подпись) (Ф.И.О.)

Sheet Перечень
A1: Перечень таблиц формы паспорта организации
A3: Раздел формы паспорта | B3: № таблицы | C3: Название таблицы формы паспорта
A4: 1 | B4: 2 | C4: 3
A5: ='раздел I'!A9:N9 -> I. ОБЩАЯ ХАРАКТЕРИСТИКА ОРГАНИЗАЦИИ | B5: б/н | C5: =Пояснит.записка!A4 -> Пояснительная записка
B6: =RIGHT('А-1'!C1,LEN('А-1'!C1)-8) -> А/1 | C6: ='А-1'!A4 -> Адресно-справочная информация об организации
B7: =RIGHT('А-2'!I1,LEN('А-2'!I1)-8) -> А/2 | C7: ='А-2'!A4 -> Сведения о филиалах и обособленных производственных подразделениях
B8: =RIGHT('А-3'!D1,LEN('А-3'!D1)-8) -> А/3 | C8: ='А-3'!A4 -> Ситуационный план организации
B9: =RIGHT('А-4'!D1,LEN('А-4'!D1)-8) -> А/4 | C9: ='А-4'!A4 -> Схема генерального плана (М 1 : 5000)
B10: =RIGHT('А-5'!D1,LEN('А-5'!D1)-8) -> А/5 | C10: ='А-5'!A4 -> Организационно-структурная схема (схема управления организацией)
B11: =RIGHT('А-6'!L1,LEN('А-6'!L1)-8) -> А/6 | C11: ='А-6'!A4 -> Сведения о дочерних, в т.ч. малых предпринимательских структурах
B12: =RIGHT('А-7'!K1,LEN('А-7'!K1)-8) -> А/7 | C12: ='А-7'!A4 -> Сведения о ценных бумагах акционерного общества и ценных бумагах его дочерних (зависимых) обществ
B13: =RIGHT('I-1'!F1,LEN('I-1'!F1)-8) -> I/1 | C13: ='I-1'!A4 -> Сведения о лицензиях на виды деятельности
B14: =RIGHT('I-2'!N1,LEN('I-2'!N1)-8) -> I/2 | C14: ='I-2'!A4 -> Сведения о сертификатах соответствия (заключениях)
B15: =RIGHT('I-3'!C1,LEN('I-3'!C1)-8) -> I/3 | C15: ='I-3'!A4 -> Информация об официальном аудиторе организации
B16: =RIGHT('I-4'!K1,LEN('I-4'!K1)-8) -> I/4 | C16: ='I-4'!A4 -> Сведения об имущественных правах акционеров (участников) организации (холдинга)
B17: =RIGHT('I-5'!L1,LEN('I-5'!L1)-8) -> I/5 | C17: ='I-5'!A4 -> Сведения об участии в других организациях
B18: =RIGHT('I-6'!D1,LEN('I-6'!D1)-8) -> I/6 | C18: ='I-6'!A4 -> Сведения о совете директоров общества
A19: ='раздел II'!A9:O9 -> II. ВЫПОЛНЕНИЕ СЕРИЙНЫХ ПОСТАВОК ПРОДУКЦИИ | B19: =RIGHT('II-1'!K1,LEN('II-1'!K1)-8) -> II/1 | C19: ='II-1'!B4 -> Отчет о ходе выполнения и финансирования поставок продукции военного и специального назначения (работ, услуг) по государственному оборонному заказу
B20: =RIGHT('II-2'!I1,LEN('II-2'!I1)-8) -> II/2 | C20: ='II-2'!A4 -> Выпускаемая продукция, основные технические переделы и «узкие места»
B21: =RIGHT('II-3'!J1,LEN('II-3'!J1)-8) -> II/3 | C21: ='II-3'!A4 -> «Узкие места» производственного процесса изделий РКТ в организации (на плановый период)
B22: =RIGHT('II-4'!I1,LEN('II-4'!I1)-8) -> II/4 | C22: ='II-4'!A4 -> Кооперационные связи организации
A23: ='раздел III'!A9:O9 -> III. ВЫПОЛНЕНИЕ НИОКР ПО СПЕЦПРОДУКЦИИ | B23: =RIGHT('III-1'!K1,LEN('III-1'!K1)-8) -> III/1 | C23: ='III-1'!B4 -> Сведения об участии в реализации государственных и федеральных целевых программ
B24: =RIGHT('III-2'!J1,LEN('III-2'!J1)-8) -> III/2 | C24: ='III-2'!B4 -> Отчет о ходе выполнения и финансирования работ НИОКР по спецпродукции
B25: =RIGHT('III-3'!J1,LEN('III-3'!J1)-8) -> III/3 | C25: ='III-3'!B4 -> Планируемые НИОКР по спецпродукции
A26: ='раздел IV'!A9 -> IV. ВЫПОЛНЕНИЕ РАБОТ ПО ПРОДУКЦИИ ГРАЖДАНСКОГО НАЗНАЧЕНИЯ | B26: =RIGHT('IV-1'!O1,LEN('IV-1'!O1)-8) -> IV/1 | C26: ='IV-1'!A4 -> Производство продукции гражданского назначения, товаров народного потребления и услуг, оказанных организацией
B27: =RIGHT('IV-2'!C1,LEN('IV-2'!C1)-8) -> IV/2 | C27: ='IV-2'!A5 -> Ожидаемое развитие, виды технологий и проблемы реализации программы товаров народного потребления. Выделенные производственные площади и оборудование
B28: =RIGHT('IV-3'!G1,LEN('IV-3'!G1)-8) -> IV/3 | C28: ='IV-3'!B4 -> Инновационные проекты по продукции гражданского и двойного назначения
A29: ='раздел V'!A9 -> V. ВЫПОЛНЕНИЕ РАБОТ ПО ГОСУДАРСТВЕННЫМ КОНТРАКТАМ | B29: =RIGHT('V-1'!L1,LEN('V-1'!L1)-8) -> V/1 | C29: ='V-1'!A4 -> Продукция отечественных производителей, закупаемая в обеспечение выполнения государственных контрактов (контрактов)
B30: =RIGHT('V-2'!L1,LEN('V-2'!L1)-8) -> V/2 | C30: ='V-2'!A4 -> Продукция, импортируемая в обеспечение выполнения государственных контрактов (контрактов)
B31: =RIGHT('V-3'!J1,LEN('V-3'!J1)-8) -> V/3 | C31: ='V-3'!A4 -> Сведения о продукции (материалах и комплектующих), используемой при выполнении государственных контрактов (контрактов), производство которой прекращено (приостановлено) или находится за пределами Российской Федерации и импорт которой ограничен
A32: ='раздел VI'!B9 -> VI. ПРОИЗВОДСТВЕННО-ТЕХНОЛОГИЧЕСКАЯ БАЗА | B32: =RIGHT('VI-1'!K1,LEN('VI-1'!K1)-8) -> VI/1 | C32: ='VI-1'!B4 -> Производственные основные фонды - возрастной состав оборудования
B33: =RIGHT('VI-2'!I1,LEN('VI-2'!I1)-8) -> VI/2 | C33: ='VI-2'!B4 -> Кодифицированный перечень подразделений по видам производства
B34: =RIGHT('VI-3'!J1,LEN('VI-3'!J1)-8) -> VI/3 | C34: ='VI-3'!B4 -> Состав оборудования организации по видам производств
B35: =RIGHT('VI-4'!K1,LEN('VI-4'!K1)-8) -> VI/4 | C35: ='VI-4'!C5 -> Трудоемкость годовой программы товарного выпуска продукции по видам производств
B36: =RIGHT('VI-5'!M1,LEN('VI-5'!M1)-8) -> VI/5 | C36: ='VI-5'!B3 -> Сведения о приобретенном оборудовании в отчетном году
B37: =RIGHT('VI-6'!H1,LEN('VI-6'!H1)-8) -> I/6 | C37: ='VI-6'!B4 -> Сведения об оборудовании, запланированном к закупке
B38: =RIGHT('VI-7'!N1,LEN('VI-7'!N1)-8) -> #VALUE! | C38: ='VI-7'!B3 -> Данные по инвестиционным проектам
B39: =RIGHT('VI-8'!K1,LEN('VI-8'!K1)-8) -> VI/8 | C39: ='VI-8'!A4 -> Сведения об арендованном (лизинговом) и полученном на ответственное хранение оборудовании за отчетный год
B40: =RIGHT('VI-9'!I1,LEN('VI-9'!I1)-8) -> VI/9 | C40: ='VI-9'!B4 -> Сведения об оборудовании, переданном в залог или обременённом иным образом (за исключением оборудования, сданного в аренду) в отчетном году
B41: =RIGHT('VI-10'!I1,LEN('VI-10'!I1)-8) -> VI/10 | C41: ='VI-10'!A4 -> Сведения об оборудовании организации, сданном в аренду в отчетном году
...

Sheet раздел I
A9: I. ОБЩАЯ ХАРАКТЕРИСТИКА ОРГАНИЗАЦИИ

Sheet Пояснит.записка
A2: Сокращенное название организации
A4: Пояснительная записка
A5: к паспорту _________________________________________
C6: полное название предприятия
A7: по состоянию на «_____»______________20_____ года
A9: Файл:
B12: Подпись
C13: должность, Ф.И.О. исполнителя и его контактный телефон

Sheet А-1
C1: Таблица А/1
A2: Сокращенное название организации
A4: Адресно-справочная информация об организации
A6: Код строки | B6: Показатель | C6: Значение показателя
A7: 1 | B7: 2 | C7: 3
A8: 100 | B8: Полное наименование организации
A9: 101 | B9: Сокращенное наименование организации
A10: 110 | B10: Юридический адрес: | C10: Х
A11: 111 | B11: Почтовый индекс
A12: 112 | B12: Республика, край, область
A13: 113 | B13: Район, населенный пункт
A14: 114 | B14: Улица, номер дома, корпус или строение
A15: 120 | B15: Почтовый адрес: | C15: X
A16: 121 | B16: Почтовый индекс
A17: 122 | B17: Республика, край, область
A18: 123 | B18: Район, населенный пункт
A19: 124 | B19: Улица, номер дома, корпус или строение
A20: 130 | B20: Телефон
A21: 131 | B21: Факс
A22: 132 | B22: Адрес электронной почты
A23: 133 | B23: Сайт организации
A24: 133 | B24: Должность, фамилия, имя, отчество руководителя
A25: 140 | B25: Когда и на каком основании (дата и номер документа) создана организация
A26: 141 | B26: Основной государственный регистрационный номер записи о создании юридического лица, внесенный в ЕГРЮЛ
A27: 142 | B27: Дата выдачи свидетельства о внесении изменений в ЕГРЮЛ
... A55: 600 | B55: Примечания
B58: Подпись
B59: должность, Ф.И.О. исполнителя и его контактный телефон

Sheet А-2
C1: I-2 | I1: Таблица А/2
A2: Сокращенное название организации
A4: Сведения о филиалах и обособленных производственных подразделениях
A6: № п/п | B6: Полное название | C6: Краткое название | D6: Почтовый адрес | H6: Специализация, основные виды выпускаемой продукции | I6: Примечания
D7: индекс | E7: республика, край, область | F7: район, населенный пункт | G7: улица, номер дома, корпус или строение
A8: 1 | B8: 2 | C8: 3 | D8: 4 | E8: 5 | F8: 6 | G8: 7 | H8: 8 | I8: 9
F12: Подпись
G13: должность, Ф.И.О. исполнителя и его контактный телефон

Sheet А-3
D1: Таблица А/3
A2: Сокращенное название организации
A4: Ситуационный план организации
A6: № п/п | B6: Имя файла | C6: Описание | D6: Примечание
A7: 1 | B7: 2 | C7: 3 | D7: 4
B12: Подпись
C13: должность, Ф.И.О. исполнителя и его контактный телефон

Sheet А-4
D1: Таблица А/4
A2: Сокращенное название организации
A4: Схема генерального плана (М 1 : 5000)
A6: № п/п | B6: Имя файла | C6: Описание | D6: Примечание
A7: 1 | B7: 2 | C7: 3 | D7: 4
B11: Подпись
C12: должность, Ф.И.О. исполнителя и его контактный телефон

Sheet А-5
D1: Таблица А/5
A2: Сокращенное название организации
A4: Организационно-структурная схема (схема управления организацией)
B9: Подпись
C10: должность, Ф.И.О. исполнителя и его контактный телефон

Sheet А-6
L1: Таблица А/6
A2: Сокращенное название организации
A4: Сведения о дочерних, в т.ч. малых предпринимательских структурах
A6: № п/п | B6: Полное и краткое наименование дочерних, в т.ч. малых предпринимательс- ких структур (по Уставу) | C6: Код ОКОПФ | D6: Состав учредителей | E6: Доля учредителей в уставном капитале, % | F6: Тип вклада учредителей в уставных капитал (денежный, оборудование, площади и т.п.) | G6: Юридический адрес (фактический адрес) | H6: Номер в Гос- реестре/дата регистрации | I6: Виды деятельности по Уставу, в т.ч. основной вид деятельности | J6: Наличие лицензии или другого разрешающего документа на работы по РКТ (номер, дата выдачи, срок действия) | K6: Годовой объем продукции (работ, услуг), млн. руб. за год
K7: всего | L7: в т.ч. РКТ
A8: 1 | B8: 2 | C8: 3 | D8: 4 | E8: 5 | F8: 6 | G8: 7 | H8: 8 | I8: 9 | J8: 10 | K8: 11 | L8: 12
H12: Подпись
I13: должность, Ф.И.О. исполнителя и его контактный телефон

Sheet А-7
K1: Таблица А/7
A2: Сокращенное название организации
A4: Сведения о ценных бумагах акционерного общества и ценных бумагах его дочерних (зависимых) обществ
A6: № п/п | B6: Наименование дочернего (зависимого) общества | C6: Категория (тип) ценных бумаг | D6: Дата выпуска (эмиссии) | E6: Объем эмиссии руб. | F6: Номинальная стоимость ценной бумаги на дату заполнения паспорта, руб. | G6: Дата (ы) изменения номинала ценных бумаг (если проводилось) и пропорции изменения, % | H6: Сроки конвертации (для конверти- руемых бумаг) | I6: Срок погашения (для облигаций) | J6: Доходность облигаций (дивиденд за последний отчетный год для акций), % к номиналу | K6: Рыночная стоимость акции (облигации) на дату заполнения паспорта (при наличии котировок), руб.
A7: 1 | B7: 2 | C7: 3 | D7: 4 | E7: 5 | F7: 6 | G7: 7 | H7: 8 | I7: 9 | J7: 10 | K7: 11
G11: Подпись
H12: должность, Ф.И.О. исполнителя и его контактный телефон

Sheet I-1
F1: Таблица I/1
A2: Сокращенное название организации
A4: Сведения о лицензиях на виды деятельности
A6: Вид деятельности | B6: Группы продукции по ЕКПС, указанные в лицензии | C6: Лицензия | F6: Срок действия лицензии
C7: номер | D7: дата | E7: кем выдана
A8: 1 | B8: 2 | C8: 3 | D8: 4 | E8: 5 | F8: 6
C12: Подпись
D13: должность, Ф.И.О. исполнителя и его контактный телефон
A14: ЕКПС - единый классификатор предметов снабжения

Sheet I-2
N1: Таблица I/2
A2: Сокращенное название организации
A4: Сведения о сертификатах соответствия (заключениях)
A6: № п/п | B6: Наименование | D6: Реквизиты | I6: Область действия | N6: Реквизиты документа, которым соответствует объект сертификации (наименование, обозначение ГОСТ, ТУ и т.д.) | O6: Номер ВП, № и дата согласования им сертификата, заключения
B7: орган по сертификации | C7: система сертификации | D7: наименование, обозначение документа | E7: номер | F7: дата выдачи | G7: срок действия | I7: наименование (сертификата, заключения) | J7: объект сертификации (система менеджмента качества, продукция, технологический процесс, производство, система управления окружающей средой, система управления охраной труда, иное) | K7: системы менеджмента качества
G8: дата начала | H8: дата окончания | K8: по видам деятельности (разработка, производство, ремонт, утилизация и т.д.) | L8: по кодам ЕКПС | M8: по кодам ОКП (по видам и типам продукции)
A9: 1 | B9: 2 | C9: 3 | D9: 4 | E9: 5 | F9: 6 | G9: 7 | H9: 8 | I9: 9 | J9: 10 | K9: 11 | L9: 12 | M9: 13 | N9: 14 | O9: 15
J14: Подпись
K15: должность, Ф.И.О. исполнителя и его контактный телефон

Sheet I-3
C1: Таблица I/3
A2: Сокращенное название организации
A4: Информация об официальном аудиторе организации
A6: № п/п | B6: Показатель | C6: Значение показателя
A7: 1 | B7: 2 | C7: 3
A8: 1 | B8: Дата проведения конкурсного отбора аудиторской организации и результаты проведения конкурса
A9: 2 | B9: Полное наименование официального аудитора, его юридический и фактический адреса, номера телефонов, факсов, электронной почты
A10: 3 | B10: Сокращенное наименование официального аудитора
A11: 4 | B11: Номер, дата выдачи и срок действия лицензии на осуществление аудиторской деятельности в соответствующей области, выданной в установленном порядке Минфином России
B14: Подпись
C15: должность, Ф.И.О. исполнителя и его контактный телефон

Sheet I-4
K1: Таблица I/4
A2: Сокращенное название организации
A4: Сведения об имущественных правах акционеров (участников) организации (холдинга)
A6: № п.п. | B6: Наименование организации | C6: ОКПО | D6: Город | E6: Имущественные права акционеров (участников) на начало и конец отчетного года
E7: акционер (участник) | F7: доля в капитале, % | H7: доля голосующих акций, % | J7: специальное право («золотая акция»)
F8: на 01 января | G8: на 31 декабря | H8: на 01 января | I8: на 31 декабря | J8: на 01 января | K8: на 31 декабря
A9: 1 | B9: 2 | C9: 3 | D9: 4 | E9: 5 | F9: 6 | G9: 7 | H9: 8 | I9: 9 | J9: 10 | K9: 11
G13: Подпись
H14: должность, Ф.И.О. исполнителя и его контактный телефон

Sheet I-5
L1: Таблица I/5
A2: Сокращенное название организации
A4: Сведения об участии в других организациях
A6: № п/п | B6: Наименование организации | C6: Доля в уставном капитале, % | E6: Доля голосующих акций, % | G6: Стоимость доли в уставном капитале, рублей | I6: Количество обыкновенных акций акций, шт. | K6: Количество привилегированных акций, шт.
C7: на 01 января | D7: на 31 декабря | E7: на 01 января | F7: на 31 декабря | G7: на 01 января | H7: на 31 декабря | I7: на 01 января | J7: на 31 декабря | K7: на 01 января | L7: на 31 декабря
A8: 1 | B8: 2 | C8: 3 | D8: 4 | E8: 5 | F8: 6 | G8: 7 | H8: 8 | I8: 9 | J8: 10 | K8: 11 | L8: 12
G12: Подпись
H13: должность, Ф.И.О. исполнителя и его контактный телефон

Sheet I-6
D1: Таблица I/6
A2: Сокращенное название организации
A4: Сведения о совете директоров общества
A6: № п/п | B6: Ф.И.О. | C6: Должность | D6: Доля акций общества, %
A7: 1 | B7: 2 | C7: 3 | D7: 4
A8: Состав совета директоров на 01.01 отчетного года
A9: Правоустанавливающий документ
A12: Дата начала работы Совета директоров в измененном составе на ____ отчетного года
A13: Правоустанавливающий документ
B18: Подпись
C19: должность, Ф.И.О. исполнителя и его контактный телефон

Sheet раздел II
A9: II. ВЫПОЛНЕНИЕ СЕРИЙНЫХ ПОСТАВОК ПРОДУКЦИИ

Sheet II-1
K1: Таблица II/1
B2: Сокращенное название организации
B4: Отчет о ходе выполнения и финансирования поставок продукции военного и специального назначения (работ, услуг) по государственному оборонному заказу
K6: Цены указываются без НДС | T6: Цены указываются без НДС | Z6: Цены указываются без НДС
A7: № п/п | B7: Продукция (работы, услуги) | E7: Государственный заказчик, заказчик | F7: Государствен- ные контракты, контракты (номер, дата и срок действия) | G7: Единица измерения количества продукции | H7: Использование базовых и критических промышленных технологий (если есть) | L7: Предусмотрено контрактами на отчетный год | N7: Предусмотрено контрактами на периоды, следующие за отчетным годом (количество) | O7: Запасы на складе на начало отчетного года (количество) | P7: Произведено за отчетный год | R7: Отгружено заказчику за отчетный год | T7: Остатки на складах на конец отчетного года (количество) | U7: Оплачено Заказчиком за отчетный год, тыс.руб | V7: Задолженность организации перед Заказчиком либо задолженность Заказчика (гр.22 со знаком минус) перед организацией на конец отчетного периода года | X7: Доля собственных работ в себестоимости продукции, (работ, услуг) (в %) | Y7: Сумма комиссий, взимаемой ОАО «Рособоронэкспорт», тыс. руб. | Z7: Примечания
B8: наименование | C8: код ОКПД 2 | D8: код ЕКПС | H8: наименование | I8: признак и вид | J8: номер | K8: шифр | L8: кол-во | M8: стоимость, тыс. руб. | P8: кол-во | Q8: стоимость, тыс. руб. | R8: кол-во | S8: стоимость, тыс. руб. | V8: кол-во | W8: стоимость, тыс. руб.
A9: 1 | B9: 2 | C9: 3 | D9: 4 | E9: 5 | F9: 6 | G9: 7 | H9: 8 | I9: 9 | J9: 10 | K9: 11 | L9: 12 | M9: 13 | N9: 14 | O9: 15 | P9: 16 | Q9: 17 | R9: 18 | S9: 19 | T9: 20 | U9: 21 | V9: 22 | W9: 23 | X9: 24 | Y9: 25 | Z9: 26
B10: 1. Поставки продукции ( работ, услуг) по государственным контрактам ГОЗ
B13: 2. Поставки продукции ( работ, услуг) по контрактам ГОЗ (соисполнительство)
B16: 3. Поставки продукции (работ, услуг) по договорам комиссии с ОАО «Рособоронэкспорт»
B19: 4. Поставка продукции (работ, услуг) по другим контрактам
W23: Подпись
X24: должность, Ф.И.О. исполнителя и его контактный телефон

Sheet II-2
I1: Таблица II/2
A2: Сокращенное название организации
A4: Выпускаемая продукция, основные технические переделы и «узкие места»
A6: № п/п | B6: Наименование выпускаемой товарной продукции | C6: Маршрут по: | D6: Наличие «узких мест» по технологическим переделам
C7: технологическим переделам | D7: причины (Кзаг., износ и пр.) | E7: предлагаемые мероприятия по их устранению | F7: срок реализации, года | H7: объем финансирования, млн.руб.
F8: начало | G8: окончание | H8: из бюджета | I8: из собственных средств
A9: 1 | B9: 2 | C9: 3 | D9: 4 | E9: 5 | F9: 6 | G9: 7 | H9: 8 | I9: 9
E13: Подпись
F14: должность, Ф.И.О. исполнителя и его контактный телефон

Sheet II-3
J1: Таблица II/3
A2: Сокращенное название организации
A4: «Узкие места» производственного процесса изделий РКТ в организации (на плановый период)
A6: № п/п | B6: Проблема, «узкое место» производства | C6: Основные мероприятия по расшивке «узкого места» | D6: Затраты | G6: Эффект от расшивки «узкого места» | H6: Основание для проведения работ | I6: Исполнители | J6: Примечание
D7: min/max по годам
D8: 1 год | E8: 2 год | F8: 3 год
A9: 1 | B9: 2 | C9: 3 | D9: 4 | E9: 5 | F9: 6 | G9: 7 | H9: 8 | I9: 9 | J9: 10
G13: Подпись
H14: должность, Ф.И.О. исполнителя и его контактный телефон

Sheet II-4
I1: Таблица II/4
A2: Сокращенное название организации
A4: Кооперационные связи организации
A6: № п/п | B6: Название поставщика, дислокация | D6: Поставляемая продукция | F6: Применяемость: | H6: Наименование изделия (товарной продукции) | I6: Предприятие потребитель изделия
B7: организация | C7: город | D7: наименование | E7: количество, шт./ в год. | F7: наименование ДСЕ | G7: количество на ДСЕ
A8: 1 | B8: 2 | C8: 3 | D8: 4 | E8: 5 | F8: 6 | G8: 7 | H8: 8 | I8: 9
F12: Подпись
G13: должность, Ф.И.О. исполнителя и его контактный телефон

Sheet раздел III
A9: III. ВЫПОЛНЕНИЕ НИОКР ПО СПЕЦПРОДУКЦИИ

Sheet III-1
K1: Таблица III/1
B2: Сокращенное название организации
B4: Сведения об участии в реализации государственных и федеральных целевых программ
K6: (тыс. рублей)
A7: № п/п | B7: Мероприятия, наименование программы (подпрограммы, ФЦП) и направления финансирования | C7: КБК | D7: Направлено на создание (применение) базовых и критических промышленных технологий | H7: Образец ВВСТ, в интересах которого выполняется работа | J7: Сроки реализации мероприятий | L7: Общий объем финансирования мероприятий программы | O7: Объем средств, израсходованных на реализацию программы, в отчетном году | R7: Объем средств, планируемых на реализацию программы в следующем году | U7: Результаты от реализации мероприятий | V7: Примечание
H8: наименование | I8: код по ОКПД2/ ЕКПС | J8: начало | K8: окончание | L8: всего | M8: в том числе за счет: | O8: всего | P8: в том числе за счет: | R8: всего | S8: в том числе за счет:
D9: наименование | E9: признак и вид | F9: номер | G9: шифр | M9: фед. бюдж. | N9: собств. средств | P9: фед. бюдж. | Q9: собств. средств | S9: фед. бюдж. | T9: собств. средств
A10: 1 | B10: 2 | C10: 3 | D10: 4 | E10: 5 | F10: 6 | G10: 7 | H10: 8 | I10: 9 | J10: 10 | K10: 11 | L10: 12 | M10: 13 | N10: 14 | O10: 15 | P10: 16 | Q10: 17 | R10: 18 | S10: 19 | T10: 20 | U10: 21 | V10: 22
B11: Наименование программы (подпрограммы, ФЦП)
B12: Мероприятие 1
B13: Наименование программы (подпрограммы, ФЦП)
B14: …
B15: Мероприятие n
B16: …
Q18: Подпись
R19: должность, Ф.И.О. исполнителя и его контактный телефон

Sheet III-2
A1: III-1 | J1: Таблица III/2
B2: Сокращенное название организации
B4: Отчет о ходе выполнения и финансирования работ НИОКР по спецпродукции
I6: ( в тыс. руб. без НДС)
A7: № п/п | B7: Вид работы | C7: Наименование работы | D7: Шифр темы | E7: Госзаказчик, (заказчик) | F7: № контракта (договора) | G7: Источник финансирования | H7: Признак и вид технологии | I7: Номер технологии | J7: Шифр технологии | K7: Образец ВВСТ в интересах которого выполнялась работа | N7: Этап ЖЦ | O7: Сроки исполнения работы в т.ч. этапа (этапов) | Q7: Полная стоимость (лимитная цена) работы | S7: Фактически оплачено с начала выполнения | U7: Объем выполненных работ за отчетный год | Y7: Ассигнования соисполнителям в отчетном году | Z7: Примечание
K8: название | L8: код ОКПД 2 | M8: код ЕКПС | O8: начало | P8: окончание | Q8: всего | R8: собств. средства | S8: всего | T8: из собств. средств | U8: план, всего | V8: план, из собств. средств | W8: факт, всего | X8: факт, из собств. средств
A10: 1 | B10: 2 | C10: 3 | D10: 4 | E10: 5 | F10: 6 | G10: 7 | H10: 8 | I10: 9 | J10: 10 | K10: 11 | L10: 12 | M10: 13 | N10: 14 | O10: 15 | P10: 16 | Q10: 17 | R10: 18 | S10: 19 | T10: 20 | U10: 21 | V10: 22 | W10: 23 | X10: 24 | Y10: 25 | Z10: 26
B11: 1. НИОКР, выполняемые по государственным и федеральным целевым программмам
B12: 1.1 Поставка научно-технической продукции по государственным контрактам
B14: 1.2 Поставка научно-технической продукции по контрактам
B17: 2. НИОКР, выполняемые по заданиям ГОЗ
B18: 2.1 Поставка научно-технической продукции по государственным контрактам
B21: 2.2 Поставка научно-технической продукции по контрактам
B24: 3. НИОКР, выполняемые по договорам ВТС
B25: 3.1 Поставка научно-технической продукции по государственным контрактам
B28: 3.2 Поставка научно-технической продукции по контрактам
B31: 4. Выполнение инициативных НИОКР (за счет собственных средств)
W34: Подпись
X35: должность, Ф.И.О. исполнителя и его контактный телефон

Sheet III-3
A1: III-1 | J1: Таблица III/3
B2: Сокращенное название организации
B4: Планируемые НИОКР по спецпродукции
J5: ( в тыс. руб. без НДС)
A6: № п/п | B6: Вид работы | C6: Наименование работы | D6: Шифр темы | E6: Госзаказчик, (заказчик) | F6: № контракта (договора) | G6: Источник финанси-рования | H6: Признак и вид технологии | I6: Номер технологии | J6: Шифр технологии | K6: Образец ВВСТ в интересах которого выполнялась работа | N6: Этап ЖЦ | O6: Сроки исполнения работы в т.ч. этапа (этапов) | Q6: Полная стоимость (лимитная цена) работы | S6: Объемы, запланированные на следующие за отчетным годы | U6: Примечание
K8: название | L8: код ОКПД 2 | M8: код ЕКПС | O8: начало | P8: окончание | Q8: всего | R8: из собств. средств | S8: всего | T8: из собств. средств
A9: 1 | B9: 2 | C9: 3 | D9: 4 | E9: 5 | F9: 6 | G9: 7 | H9: 8 | I9: 9 | J9: 10 | K9: 11 | L9: 12 | M9: 13 | N9: 14 | O9: 15 | P9: 16 | Q9: 17 | R9: 18 | S9: 19 | T9: 20 | U9: 21
B10: 1. НИОКР, выполняемые по государственным и федеральным целевым программмам
B11: 1.1 Поставка научно-технической продукции по государственным контрактам
B13: 1.2 Поставка научно-технической продукции по контрактам
B15: 2. НИОКР, выполняемые по заданиям ГОЗ
B16: 2.1 Поставка научно-технической продукции по государственным контрактам
B18: 2.2 Поставка научно-технической продукции по контрактам
B20: 3. НИОКР, выполняемые по договорам ВТС
B21: 3.1 Поставка научно-технической продукции по государственным контрактам
B23: 3.2 Поставка научно-технической продукции по контрактам
B25: 4. Выполнение инициативных НИОКР (за счет собственных средств)
Q28: Подпись
R29: должность, Ф.И.О. исполнителя и его контактный телефон

Sheet раздел IV
A9: IV. ВЫПОЛНЕНИЕ РАБОТ ПО ПРОДУКЦИИ ГРАЖДАНСКОГО НАЗНАЧЕНИЯ

Sheet IV-1
A1: IV-1 | O1: Таблица IV/1
A2: Сокращенное название организации
A4: Производство продукции гражданского назначения, товаров народного потребления и услуг, оказанных организацией
O6: Суммы указывать без НДС
A7: № п/п | B7: Наименование продукции (услуг) | C7: Код ОКПД2 | D7: Единица измерения | E7: Плановый объем производства продукции | G7: Фактический объем произведенной продукции | I7: Фактический объем реализованной продукции | K7: Объём поставок ПГН на экспорт | M7: Остатки готовой продукции на складе на конец года | O7: Примечания
E9: кол-во | F9: тыс.руб. | G9: кол-во | H9: тыс.руб. | I9: кол-во | J9: тыс.руб. | K9: кол-во | L9: тыс.руб. | M9: кол-во | N9: тыс.руб.
A10: 1 | B10: 2 | C10: 3 | D10: 4 | E10: 5 | F10: 6 | G10: 7 | H10: 8 | I10: 9 | J10: 10 | K10: 11 | L10: 12 | M10: 13 | N10: 14 | O10: 15
I14: Подпись
J15: должность, Ф.И.О. исполнителя и его контактный телефон

Sheet IV-2
C1: Таблица IV/2
A3: Сокращенное название организации
A5: Ожидаемое развитие, виды технологий и проблемы реализации программы товаров народного потребления. Выделенные производственные площади и оборудование
A7: № п/п | B7: Направления развития | C7: Решения
A8: 1 | B8: 2 | C8: 3
A9: 1 | B9: Социальные меры поддержки программы производства ПГН и ТНП
A10: 2 | B10: Ожидаемое развитие:
A11: 2.1 | B11: – по выпуску ПГН и ТНП
A12: 2.2 | B12: – по изменению состава выпускаемой продукции
A13: 2.3 | B13: – по постановке на производство новых видов ПГН и ТНП
A14: 3 | B14: Базовые технологии при производстве ПГН, ТНП и их развитие
A15: 4 | B15: Какие производственные площади используются для производства ПГН и ТНП
A16: 5 | B16: Оборудование используемое при производстве ПГН и ТНП
A17: 6 | B17: «Узкие места» при производстве ПГН и ТНП
A18: 7 | B18: Какие мероприятия планируются для расшивки «узких мест» производства ПГН и ТНП
B20: Подпись
C21: должность, Ф.И.О. исполнителя и его контактный телефон

Sheet IV-3
G1: Таблица IV/3
B2: Сокращенное название организации
B4: Инновационные проекты по продукции гражданского и двойного назначения
A6: № п/п | B6: Наименование инновационного проекта | C6: Краткое содержание проекта | D6: Код направ-ленности | E6: Степень готовности проекта | F6: Степень участия в финансировании реализации проекта, % | G6: Объем необходимых инвестиций, тыс. руб. | H6: Источники инвестиций (тыс.руб.) | L6: Сроки реализации проекта | N6: Себестоимость единицы продукции, тыс.руб. | P6: Плановый срок окупаемости проекта, лет | Q6: Рентабельность проекта, % | S6: Примечания
H7: бюджетное финанси- рование | I7: собственные средства | J7: иностранные инвестиции | K7: прочие средства | L7: начало | M7: конец | N7: плановая | O7: фактическая | Q7: плановая | R7: фактическая
A8: 1 | B8: 2 | C8: 3 | D8: 4 | E8: 5 | F8: 6 | G8: 7 | H8: 8 | I8: 9 | J8: 10 | K8: 11 | L8: 12 | M8: 13 | N8: 14 | O8: 15 | P8: 16 | Q8: 17 | R8: 18 | S8: 19
O12: Подпись
P13: должность, Ф.И.О. исполнителя и его контактный телефон

Sheet раздел V
A9: V. ВЫПОЛНЕНИЕ РАБОТ ПО ГОСУДАРСТВЕННЫМ КОНТРАКТАМ

Sheet V-1
L1: Таблица V/1
A2: Сокращенное название организации
A4: Продукция отечественных производителей, закупаемая в обеспечение выполнения государственных контрактов (контрактов)
A6: № п/п | B6: Наименовании продукции, для которой осуществлялась закупка | C6: Государственный(е) контракт(ы) (контракт(ы) | D6: Доля собственных работ в себестоимости продукции, (в %) | E6: Закупаемая продукция (материалы, комплектующие и пр.) | I6: Объем закупок | L6: Примечания
E7: наименование | F7: код ОКПД2 | G7: код ЕКПС | H7: организация-поставщик | I7: единица измерения количества продукции | J7: количество | K7: стоимость, тыс.руб
A8: 1 | B8: 2 | C8: 3 | D8: 4 | E8: 5 | F8: 6 | G8: 7 | H8: 8 | I8: 9 | J8: 10 | K8: 11 | L8: 12
H12: Подпись
I13: должность, Ф.И.О. исполнителя и его контактный телефон

Sheet V-2
L1: Таблица V/2
A2: Сокращенное название организации
A4: Продукция, импортируемая в обеспечение выполнения государственных контрактов (контрактов)
A6: № п/п | B6: Наименование продукции, для которой осуществлялась закупка | C6: Государст-венный(е) контракт(ы) (контракт(ы) | D6: Доля собственных работ в себестоимости продукции, (в %) | E6: Закупаемая продукция (материалы, комплектующие и пр.) | I6: Объем закупок | L6: Примечания
E7: наименование | F7: код ОКПД2 | G7: страна происхождения | H7: производитель | I7: единица измерения количества продукции | J7: количество | K7: стоимость, тыс. долл. США
A8: 1 | B8: 2 | C8: 3 | D8: 4 | E8: 5 | F8: 6 | G8: 7 | H8: 8 | I8: 9 | J8: 10 | K8: 11 | L8: 12
H12: Подпись
I13: должность, Ф.И.О. исполнителя и его контактный телефон

Sheet V-3
J1: Таблица V/3
A2: Сокращенное название организации
A4: Сведения о продукции (материалах и комплектующих), используемой при выполнении государственных контрактов (контрактов), производство которой прекращено (приостановлено) или находится за пределами Российской Федерации и импорт которой ограничен
A6: № п/п | B6: Продукция, при производстве которой используется | C6: Государственный контракт (контракт) | D6: Закупаемая продукция (материалы, комплектующие и пр.) | H6: Единица измерения количества | I6: Потребность | J6: Наличие на складе
D7: наименование | E7: код ОКПД2 | F7: страна происхождения | G7: производитель (бывший производитель)
A8: 1 | B8: 2 | C8: 3 | D8: 4 | E8: 5 | F8: 6 | G8: 7 | H8: 8 | I8: 9 | J8: 10
F12: Подпись
G13: должность, Ф.И.О. исполнителя и его контактный телефон

Sheet раздел VI
B9: VI. ПРОИЗВОДСТВЕННО-ТЕХНОЛОГИЧЕСКАЯ БАЗА

Sheet VI-1
A1: V-1 | K1: Таблица VI/1
B2: Сокращенное название организации
B4: Производственные основные фонды - возрастной состав оборудования
A6: Код строки | B6: Наименование оборудования по его применению в различных видах деятельности | C6: Количество оборудования на конец года ед. | F6: Из установленного оборудования – оборудование в возрасте, единиц Из установленного оборудования – оборудование в возрасте, единиц Из установленного оборудования – оборудование в возрасте, единиц | AE6: Примечание
C7: всего | D7: введенное в эксплуатацию в отчетном году | E7: импортное оборудование | F7: до 5 лет | K7: от 5 до 10 лет | P7: от 10 до 15 лет | U7: от 15 до 20 лет | Z7: свыше 20 лет
F8: всего | G8: импортного оборудования | H8: коэффициент использования оборудования в производстве | J8: средневзвешенный коэффициент загрузки | K8: всего | L8: импортного оборудования | M8: коэффициент использования оборудования в производстве | O8: средневзвешенный коэффициент загрузки | P8: всего | Q8: импортного оборудования | R8: коэффициент использования оборудования в производстве | T8: средневзвешенный коэффициент загрузки | U8: всего | V8: импортного оборудования | W8: коэффициент использования оборудования в производстве | Y8: средневзвешенный коэффициент загрузки | Z8: всего | AA8: импортного оборудования | AB8: коэффициент использования оборудования в производстве | AD8: средневзвешенный коэффициент загрузки
H9: ПВН | I9: ПГиДН | M9: ПВН | N9: ПГиДН | R9: ПВН | S9: ПГиДН | W9: ПВН | X9: ПГиДН | AB9: ПВН | AC9: ПГиДН
A10: 1 | B10: 2 | C10: 3 | D10: 4 | E10: 5 | F10: 6 | G10: 7 | H10: 8 | I10: 9 | J10: 10 | K10: 11 | L10: 12 | M10: 13 | N10: 14 | O10: 15 | P10: 16 | Q10: 17 | R10: 18 | S10: 19 | T10: 20 | U10: 21 | V10: 22 | W10: 23 | X10: 24 | Y10: 25 | Z10: 26 | AA10: 27 | AB10: 28 | AC10: 29 | AD10: 30 | AE10: 31
A11: 100 | B11: Станочный парк и оборудование всего по организации в т.ч. по видам производства:
A12: 101 | B12: Металлургическое производство
A13: 102 | B13: Производство оптических материалов и оптических сред
A14: 103 | B14: Литейное производство
A15: 104 | B15: Кузнечно-прессовое производство
A16: 105 | B16: Механообрабатывающее производство
A17: 106 | B17: Изготовление оптических деталей
A18: 107 | B18: Быстрое прототипирование и изготовление деталей на основе аддитивных технологий
A19: 108 | B19: Химическое производство
A20: 109 | B20: Гальванохимическое производство
A21: 110 | B21: Термическое и химико-термическое производство
A22: 111 | B22: Нанесение защитных покрытий
... A43: 132 | B43: Прочие виды производства
A44: 200 | B44: Уникальное станочное оборудование | H44: Х | I44: Х | J44: Х | M44: Х | N44: Х | O44: Х | R44: Х | S44: Х | T44: Х | W44: Х | X44: Х | Y44: Х | AB44: Х | AC44: Х | AD44: Х
A45: 300 | B45: Универсальные станки с ЧПУ | H45: Х | I45: Х | J45: Х | M45: Х | N45: Х | O45: Х | R45: Х | S45: Х | T45: Х | W45: Х | X45: Х | Y45: Х | AB45: Х | AC45: Х | AD45: Х
A46: 400 | B46: Гибкие производственные системы и автоматические линии | H46: Х | I46: Х | J46: Х | M46: Х | N46: Х | O46: Х | R46: Х | S46: Х | T46: Х | W46: Х | X46: Х | Y46: Х | AB46: Х | AC46: Х | AD46: Х
A47: 500 | B47: Роботы и робототехнические комплексы, программируемые манипуляторы | H47: Х | I47: Х | J47: Х | M47: Х | N47: Х | O47: Х | R47: Х | S47: Х | T47: Х | W47: Х | X47: Х | Y47: Х | AB47: Х | AC47: Х | AD47: Х
A48: 600 | B48: Количество машин, оборудования и станков, используемых в основном производстве | H48: Х | I48: Х | J48: Х | M48: Х | N48: Х | O48: Х | R48: Х | S48: Х | T48: Х | W48: Х | X48: Х | Y48: Х | AB48: Х | AC48: Х | AD48: Х
A49: 700 | B49: Объекты научно-эксперементальной стендовой базы (НЭСБ), в т.ч.: | D49: Х | E49: Х | G49: Х | H49: Х | I49: Х | J49: Х | L49: Х | M49: Х | N49: Х | O49: Х | Q49: Х | R49: Х | S49: Х | T49: Х | V49: Х | W49: Х | X49: Х | Y49: Х | AA49: Х | AB49: Х | AC49: Х | AD49: Х
A50: 710 | B50: автономные исследовательские и испытательные комплексы, в т.ч.: | D50: Х | E50: Х | G50: Х | H50: Х | I50: Х | J50: Х | L50: Х | M50: Х | N50: Х | O50: Х | Q50: Х | R50: Х | S50: Х | T50: Х | V50: Х | W50: Х | X50: Х | Y50: Х | AA50: Х | AB50: Х | AC50: Х | AD50: Х
A51: 711 | B51: внесенных в Реестр УСБ | D51: Х | E51: Х | G51: Х | H51: Х | I51: Х | J51: Х | L51: Х | M51: Х | N51: Х | O51: Х | Q51: Х | R51: Х | S51: Х | T51: Х | V51: Х | W51: Х | X51: Х | Y51: Х | AA51: Х | AB51: Х | AC51: Х | AD51: Х
A52: 720 | B52: автономные исследовательские и испытательные стенды, в т.ч.: | D52: Х | E52: Х | G52: Х | H52: Х | I52: Х | J52: Х | L52: Х | M52: Х | N52: Х | O52: Х | Q52: Х | R52: Х | S52: Х | T52: Х | V52: Х | W52: Х | X52: Х | Y52: Х | AA52: Х | AB52: Х | AC52: Х | AD52: Х
A53: 721 | B53: внесенных в Реестр УСБ | D53: Х | E53: Х | G53: Х | H53: Х | I53: Х | J53: Х | L53: Х | M53: Х | N53: Х | O53: Х | Q53: Х | R53: Х | S53: Х | T53: Х | V53: Х | W53: Х | X53: Х | Y53: Х | AA53: Х | AB53: Х | AC53: Х | AD53: Х
AB56: Подпись
AC57: должность, Ф.И.О. исполнителя и его контактный телефон

Sheet VI-2
I1: Таблица VI/2
B2: Сокращенное название организации
B4: Кодифицированный перечень подразделений по видам производства
A7: № п/п | B7: Наименование производственного подразделения | C7: Код подразделения | D7: Назначение | E7: Конечная продукция, в производстве которой участвует | F7: Направления предметной специализации организационно выделенных технологических мощностей (по видам конечной продукции, в производстве которой участвует) | H7: Занимаемая площадь | J7: Общая численность работающих | V7: Примечание
H8: всего | I8: производст-венная | J8: всего | K8: из них женщин | L8: ОПП | N8: вспомогательные рабочие | O8: руководители | P8: специалисты | U8: МОП
F9: код ОКВЭД 2 | G9: код ОКПД 2 | L9: станочники | M9: слесари | P9: исследователи | Q9: конструкторы | R9: технологи | S9: экономисты | T9: прочие
A10: 1 | B10: 2 | C10: 3 | D10: 4 | E10: 5 | F10: 6 | G10: 7 | H10: 8 | I10: 9 | J10: 10 | K10: 11 | L10: 12 | M10: 13 | N10: 14 | O10: 15 | P10: 16 | Q10: 17 | R10: 18 | S10: 19 | T10: 20 | U10: 21 | V10: 22
N14: Подпись
O15: должность, Ф.И.О. исполнителя и его контактный телефон

Sheet VI-3
J1: Таблица VI/3
B2: Сокращенное название организации
B4: Состав оборудования организации по видам производств
A6: № п/п | B6: Наименование технологии | C6: Код производственного подразделения (в соответствии с формой VI/2) | D6: Технологический процесс | F6: Группа оборудования | H6: Единица оборудования | K6: Единица оборудования (продолжение) | T6: Производственная мощность | V6: Размер | Y6: Используемое оборудование по группам | AB6: Коэффициент использования оборудования при производстве гражданской продукции (Кисп. ГП) | AC6: Коэффициент использования оборудования при производстве продукции РКТ (Кисп. РКТ) | AD6: Коэффициент загрузки оборудования при 2-сменной работе (Кзагр. ) | AE6: Средний нормативный срок эксплуатации, лет | AF6: Дата ввода в эксплуа-тации | AG6: Дата последнего капитального ремонта | AH6: Фактический износ (%) | AI6: Остаточная стоимость | AJ6: Форма приобретения (в собствен-ность, лизинг, аренда, др.) | AK6: Для оборудования, приобретенного в рамках выполнения мероприятий государственных (федеральных целевых) программ | AO6: Примечание
D7: наименование | E7: код | F7: наименование | G7: код ОКОФ | H7: идентифика-ционный код | I7: инвентарный номер | J7: наименование по техническому паспорту | K7: назначение и краткая характеристика | L7: технические характеристики конечной продукции, обрабатываемого материала, сырья, изделия, предмета обработки (изготовления) | M7: производитель (завод, фирма) | N7: страна | O7: серийный (заводской) номер | P7: год выпуска | Q7: наличие ЧПУ | R7: производитель ЧПУ | S7: дата при-обретения | T7: единица измерения | U7: значение | V7: единица измерения | W7: мин. | X7: макс. | Y7: тип | Z7: кол-во единиц | AA7: дополнитель-ные характерис-тики | AK7: государст-венная программа | AL7: источник финанси-рования приобре-тения | AM7: наименование инвестиционного проекта в соотвествии с проектно-сметной документацией | AN7: номер и дата заключения комиссии Минпромторга России об обоснованности приобретения импортного оборудования (в рамках Постановления Правительства РФ от 24.12.2013 № 1224)
A8: 1 | B8: 2 | C8: 3 | D8: 4 | E8: 5 | F8: 6 | G8: 7 | H8: 8 | I8: 9 | J8: 10 | K8: 11 | L8: 12 | M8: 13 | N8: 14 | O8: 15 | P8: 16 | Q8: 17 | R8: 18 | S8: 19 | T8: 20 | U8: 21 | V8: 22 | W8: 23 | X8: 24 | Y8: 25 | Z8: 26 | AA8: 27 | AB8: 28 | AC8: 29 | AD8: 30 | AE8: 31 | AF8: 32 | AG8: 33 | AH8: 34 | AI8: 35 | AJ8: 36 | AK8: 37 | AL8: 38 | AM8: 39 | AN8: 40 | AO8: 41
AM14: Подпись
AN15: должность, Ф.И.О. исполнителя и его контактный телефон

Sheet VI-4
K1: Таблица VI/4 | T1: Таблица VI/4
B3: Сокращенное название организации
C5: Трудоемкость годовой программы товарного выпуска продукции по видам производств
A7: № п/п | B7: Виды производств организации | C7: Трудоемкость товарной продукции по видам производств, тыс. н/час. | L7: Трудоемкость товарной продукции по видам производств, тыс. н/час. | S7: Мощность по производствам, тыс. н/час. | T7: К исп.
A9: 1 | B9: 2 | C9: 3 | D9: 4 | E9: 5 | F9: 6 | G9: 7 | H9: 8 | I9: 9 | J9: 10 | K9: 11 | L9: 12 | M9: 13 | N9: 14 | O9: 15 | P9: 16 | Q9: 17 | R9: 18 | S9: 19 | T9: 20
A10: 1 | B10: Механообрабатывающее
A11: 2 | B11: Литейное
A12: 3 | B12: Кузнечно-прессовое
A13: 4 | B13: Слесарно-каркасное
A14: 5 | B14: Гальванохимические и лакокрасочные покрытия
A15: 6 | B15: Переработка полимерных материалов
A16: 7 | B16: Изоляционное
A17: 8 | B17: Печатных плат
A18: 9 | B18: Приборов микроэлектроники
A19: 10 | B19: Сборочно-монтажное
A20: 11 | B20: Изделий из керамики и ферритов
A21: 12 | B21: Электроэлементов
A22: 13 | B22: Химическое
B24: Всего, тыс. н/час.
B25: Годовой объем выпуска, шт.(т)
P27: Подпись: | Q27: ______________________________________________
Q28: должность, Ф.И.О. исполнителя и его контактный телефон

Sheet VI-5
M1: Таблица VI/5
B2: Сокращенное название организации
B3: Сведения о приобретенном оборудовании в отчетном году
A5: № п/п | B5: Единица оборудования | F5: Источник финансиро-вания | G5: Государстве- нная программа | H5: Наименование инвестиционного проекта в соотвествии с проектно-сметной документацией | I5: Цех установки, производ-ство | J5: Коэффициент обновления оборудо-вания в цехе | K5: Обоснование приобретения оборудование | M5: Примечание
B6: наименование | C6: серийный (заводской) номер | D6: поставщик оборудования | E6: стоимость (тыс. руб.) | K6: номер | L6: дата
A7: 1 | B7: 2 | C7: 3 | D7: 4 | E7: 5 | F7: 6 | G7: 7 | H7: 8 | I7: 9 | J7: 10 | K7: 11 | L7: 12 | M7: 13
H11: Подпись
I12: должность, Ф.И.О. исполнителя и его контактный телефон

Sheet VI-6
H1: ТаблицаVI/6
B2: Сокращенное название организации
B4: Сведения об оборудовании, запланированном к закупке
H6: (цены с НДС)
A7: № п/п | B7: Технологический процесс | D7: Единица оборудования Единица оборудования (продолжение) | L7: Источник финансирования | M7: Государственная программа | N7: Наименование инвестиционного проекта в соотвествии с проектно-сметной документацией | O7: Планируемый год приобретения | P7: Цена за единицу, тыс. руб. | Q7: Кол-во, шт. | R7: Общая стоимость, тыс. руб. | S7: Номер и дата заключения комиссии Минпромторга России об обоснованности приобретения импортного оборудования (в рамках Постановления Правительства РФ от 24.12.2013 № 1224) | T7: Примечание
B8: наименование | C8: код | D8: наименование | E8: модель | F8: изготовитель | G8: поставщик | H8: страна происхождения | I8: назначение и краткая характеристика | J8: наличие ЧПУ | K8: производитель ЧПУ
A9: 1 | B9: 2 | C9: 3 | D9: 4 | E9: 5 | F9: 6 | G9: 7 | H9: 8 | I9: 9 | J9: 10 | K9: 11 | L9: 12 | M9: 13 | N9: 14 | O9: 15 | P9: 16 | Q9: 17 | R9: 18 | S9: 19 | T9: 20
R15: Подпись
S16: должность, Ф.И.О. исполнителя и его контактный телефон

Sheet VI-7
H1: Таблица VI/7
B2: Сокращенное название организации
B3: Данные по инвестиционным проектам
A5: № п/п | B5: Наименование проекта | C5: Краткая характеристика проекта | D5: Стадия разработки проекта или этап его осуществления | E5: Стоимость проекта (млн. руб) | F5: Период реализации | H5: Расчетный срок окупаемости, лет | I5: Долевое участие основных участников проекта | K5: Распределение финансирования | M5: Степень реализации проекта (%) | N5: Фактические затраты каждого участника проекта на конец отчетного года
F6: начало | G6: окончание | I6: участник | J6: % | K6: источник | L6: %
A7: 1 | B7: 2 | C7: 3 | D7: 4 | E7: 5 | F7: 6 | G7: 7 | H7: 8 | I7: 9 | J7: 10 | K7: 11 | L7: 12 | M7: 13 | N7: 14
I11: Подпись
J12: должность, Ф.И.О. исполнителя и его контактный телефон

Sheet VI-8
K1: Таблица VI/8
B2: Сокращенное название организации
A4: Сведения об арендованном (лизинговом) и полученном на ответственное хранение оборудовании за отчетный год
A6: № п/п | B6: Наименование оборудования | C6: Техпроцесс | E6: Количество оборудования (единиц) взятых в аренду | F6: Наименования организации арендодателя с указанием в каких целях используется арендованное оборудование | G6: Вид аренды, № арендных договоров и срок их действия | H6: Затраты на аренду оборудования (тыс. руб.) | K6: Примечания
C7: наименование | D7: код | H7: начислено в отчётном году | I7: факт за отчётный год | J7: план на текущий год
A8: 1 | B8: 2 | C8: 3 | D8: 4 | E8: 5 | F8: 6 | G8: 7 | H8: 8 | I8: 9 | J8: 10 | K8: 11
A9: 1
A10: 2
A11: 3
G13: Подпись | H13: __________________________________________________
H14: должность, Ф.И.О. исполнителя и его контактный телефон

Sheet VI-9
I1: Таблица VI/9
A2: ='VI-7'!B2 -> Сокращенное название организации
B4: Сведения об оборудовании, переданном в залог или обременённом иным образом (за исключением оборудования, сданного в аренду) в отчетном году
I6: (тыс. руб.)
A7: № п/п | B7: Наименование оборудования | C7: Инвентарный номер | D7: Наименование организаций-кредиторов | E7: Причины обременения с указанием соответствующих документов | F7: Сроки обременения | G7: Рыночная стоимость | H7: Сумма обязательств (кредитов, займов, исков и т.д.) | I7: Примечания
A8: 1 | B8: 2 | C8: 3 | D8: 4 | E8: 5 | F8: 6 | G8: 7 | H8: 8 | I8: 9
E12: Подпись
F13: должность, Ф.И.О. исполнителя и его контактный телефон

Sheet VI-10
I1: Таблица VI/10
A2: Сокращенное название организации
A4: Сведения об оборудовании организации, сданном в аренду в отчетном году
A6: № п/п | B6: Наименование оборудования, сдававшегося в аренду в течение отчётного года | C6: Количество оборудования (единиц), сданного в аренду | D6: Наименования организаций-арендаторов, с указанием в каких целях используется арендованное оборудование | E6: Вид аренды, № арендных договоров и срок их действия | F6: Остаточная стоимость (тыс. руб.) на начало отчётного года | G6: Доходы, полученные от сдачи оборудования в аренду (тыс. руб.)
G8: начислено в отчётном году | H8: факт за отчётный год | I8: план на текущий год
A13: 1 | B13: 2 | C13: 3 | D13: 4 | E13: 5 | F13: 6 | G13: 7 | H13: 8 | I13: 9
A16: ИТОГО:
E18: Подпись
F19: должность, Ф.И.О. исполнителя и его контактный телефон

Sheet VI-11
M1: Таблица VI/11
B2: ='VI-9'!A2 -> Сокращенное название организации
A4: Сведения об оборудовании, реализованном и списанном (утилизированном) в отчетном году и планируемом к реализации и списанию (утилизации)
A7: № п/п | B7: Наименование оборудования | C7: Количество оборудования | D7: ОКОФ | E7: Обоснование решения о реализации со ссылкой на соответствующие документы (решения) | F7: Наименование организаций-покупателей | G7: Даты заключения договоров о реализации | H7: Дата реализации | I7: Стоимость (тыс.руб.) | K7: Доходы от реализации за отчетный год (тыс.руб.) | M7: Примечания
I8: остаточная на дату реализации | J8: реализации
K9: план | L9: факт
A10: 1 | B10: 2 | C10: 3 | D10: 4 | E10: 5 | F10: 6 | G10: 7 | H10: 8 | I10: 9 | J10: 10 | K10: 11 | L10: 12 | M10: 13
A11: 1) реализованное оборудование за отчетный год
A12: 1 | B12: 2 | C12: 3 | E12: 4 | F12: 5 | G12: 6 | H12: 7 | I12: 8 | J12: 9 | L12: 10
A15: 2) оборудование, планируемое к реализации в следующем за отчетным году
A18: 3) списанное (утилизированное) оборудование в отчетном году
A21: 4) оборудование, планируемое к списанию (утилизации) в следующем за отчетным году
G27: Подпись
H28: должность, Ф.И.О. исполнителя и его контактный телефон

Sheet VI-12
N1: Таблица VI/12
A2: Сокращенное название организации
B3: Наличие испытательных площадок (полигонов)
A5: № п/п | B5: Объект | C5: Характер проводимых работ | D5: Наличие сооружений, площади и их назначение | G5: Имеющееся стандартное, нестандартное, специальное и испытательное оборудование | J5: Количество оборудования по возрасту, единиц
D6: № п/п | E6: площадь, кв.м | F6: назначение | G6: тип | H6: кол-во | I6: назначение | J6: до 5 лет | K6: от 5 до 10 лет | L6: от 10 до 15 лет | M6: от 15 до 20 лет | N6: св. 20 лет
A7: 1 | B7: 2 | C7: 3 | D7: 4 | E7: 5 | F7: 6 | G7: 7 | H7: 8 | I7: 9 | J7: 10 | K7: 11 | L7: 12 | M7: 13 | N7: 14
A8: 1 | B8: Объект А
A10: 2 | B10: Объект Б
A11: …
A12: ИТОГО: | F12: Х | G12: Х | I12: Х
H14: Подпись
I15: должность, Ф.И.О. исполнителя и его контактный телефон

Sheet VI-13
A1: XII-2 | G1: Таблица VI/13
B2: Сокращенное название организации
A4: Сводные сведения о стендово-испытательной базе
A6: Код строки | B6: Показатель | C6: Единица измерения | D6: Значение за отчетный год | E6: Плановое значение на следующий за отчетным год | F6: Прогнозные значения
F7: 2-й за отчетным год | G7: 3-й за отчетным год
A8: 1 | B8: 2 | C8: 3 | D8: 4 | E8: 5 | F8: 6 | G8: 7
A9: 100 | B9: Специализация организации, основные виды исследований (испытаний) | C9: –
A10: 200 | B10: Количество объектов научно-эксперементальной стендовой базы (НЭСБ), в т.ч.: | C10: шт.
A11: 210 | B11: внесенных в Реестр уникальной стендовой и испытательной базы (УСБ) Минпромторга России, в том числе: | C11: шт.
A12: 211 | B12: количество объектов УСБ, находящихся на хранении по сохранным распискам заказчика | C12: шт.
A13: 300 | B13: Количество автономных исследовательских и испытательных комплексов, в т.ч.: | C13: шт.
A14: 310 | B14: внесенных в Реестр УСБ | C14: шт.
A15: 320 | B15: количество стендов, входящих в состав испытательных комплексов, в т.ч.: | C15: шт.
A16: 321 | B16: внесенных в Реестр УСБ | C16: шт.
A17: 400 | B17: Количество автономных исследовательских и испытательных стендов, в том числе: | C17: шт.
A18: 410 | B18: внесенных в Реестр УСБ | C18: шт.
A19: 500 | B19: Количество остальных объектов (уровень «Г») НЭСБ | C19: шт.
A20: 600 | B20: Стоимость работ, связанных с использованием объектов УСБ, в т.ч.: | C20: тыс. руб.
... A30: 620 | B30: Справочно. Среднемесячная заработная плата работников, занятых на объектах УСБ | C30: тыс. руб.
A31: 700 | B31: Забалансовая стоимость объектов УСБ | C31: тыс. руб. | F31: X | G31: X
A32: 800 | B32: Штатная численность работников, занятых на объектах НЭСБ, в т.ч.: | C32: человек
A33: 801 | B33: на объектах УСБ | C33: человек
A34: 810 | B34: Фактическая численность работников, занятых на объектах НЭСБ, в т.ч.: | C34: человек
A35: 811 | B35: на объектах УСБ | C35: человек
A36: 900 | B36: Средний коэффициент загрузки объектов НЭСБ | C36: –
A37: 910 | B37: Коэффициент использования в производстве ПВН | C37: %
A38: Примечание:
A39: * - УСБ - уникальная стендовая и испытательная база.
D42: Подпись
E43: должность, Ф.И.О. исполнителя и его контактный телефон

Sheet раздел VII
A9: VII. ФИНАНСОВО-ЭКОНОМИЧЕСКАЯ ДЕЯТЕЛЬНОСТЬ

Sheet VII-1
A1: VI-1 | D1: Таблица VII/1
B2: Сокращенное название организации
A4: Бюджет доходов и расходов за отчетный год
D5: (тыс. руб.)
A6: Код строки | B6: Показатели | C6: Всего за отчетный год | D6: За предыдущий отчетному год
A8: 1 | B8: 2 | C8: 3 | D8: 4
A9: 1000 | B9: Выручка
A10: 1001 | B10: Реализация заказов, по которым организация является держателем контракта (головным исполнителем)
A11: 1002 | B11: Реализация заказов, по которым организация входит в кооперацию головного исполнителя из ИС
A12: 1003 | B12: Реализация заказов по внешней кооперации
A13: 1100 | B13: Выручка в рамках выполнения ГОЗ и ВТС
A14: 1110 | B14: На внутреннем рынке, в т.ч.:
A15: 1111 | B15: Реализация заказов, по которым организация является держателем контракта (головным исполнителем)
A16: 1112 | B16: Реализация заказов, по которым организация входит в кооперацию головного исполнителя из ИС
A17: 1113 | B17: Реализация заказов по внешней кооперации
A18: 1120 | B18: На экспорт, в т.ч.:
A19: 1121 | B19: Реализация заказов, по которым организация является держателем контракта (головным исполнителем)
A20: 1122 | B20: Реализация заказов, по которым организация входит в кооперацию головного исполнителя из ИС
... A43: 5000 | B43: Чистая прибыль (убыток)
A44: Справка по структуре доходов и поступлений
A45: 6001 | B45: Доходы от аренды недвижимости (за исключением объектов социальной сферы)
A46: 6002 | B46: Доходы от аренды других основных средств (за исключением объектов социальной сферы)
A47: 6003 | B47: Доходы от реализации недвижимости и других основных средств, нематериальных активов
A48: 6004 | B48: Доходы от деятельности объектов социальной сферы
A49: 6005 | B49: Проценты по кредитам и займам к получению
A50: 6006 | B50: Взносы в уставной капитал
A51: Справка по структуре расходов
A52: 7001 | B52: Расходы, связанные с арендой недвижимости (за исключением объектов социальной сферы)
A53: 7002 | B53: Расходы, связанные с арендой других основных средств (за исключением объектов социальной сферы)
A54: 7003 | B54: Расходы, связанные со списанием (ликвидацией) недвижимости и других основных средств
A55: 7004 | B55: Расходы на содержание объектов социальной сферы
B58: Подпись
D59: должность, Ф.И.О. исполнителя и его контактный телефон

Sheet VII-2
D1: Таблица VII/2
B3: Сокращенное название организации
A5: Бюджет движения денежных средств
D6: (тыс. руб.)
A7: Код строки | B7: Показатели | C7: Всего за отчетный год | D7: За предыдущий отчетному год
A8: 1 | B8: 2 | C8: 3 | D8: 4
A9: 1 | B9: Остаток денежных средств на начало периода
A10: 2 | B10: Текущая деятельность | C10: Х | D10: Х
A11: 3 | B11: Поступления от текущей деятельности (стр. 3.1 + стр. 3.2 + стр. 3.3 + стр. 3.4 + стр. 3.5 + стр. 3.6)
A12: 3.1 | B12: Поступления по основной предписанной деятельности (стр. 3.1.1 + 3.1.2)
A13: 3.1.1 | B13: На внутреннем рынке
A14: 3.1.2 | B14: На экспорт
A15: 3.2 | B15: Поступления по основной централизованной деятельности (стр. 3.2.1 + стр. 3.2.2)
A16: 3.2.1 | B16: На внутреннем рынке
A17: 3.2.2 | B17: На экспорт
A18: 3.3 | B18: Поступления по деятельности в области продукции гражданского назначения (стр. 3.3.1 + стр. 3.3.2)
A19: 3.3.1 | B19: На внутреннем рынке
A20: 3.3.2 | B20: На экспорт
A21: 3.4 | B21: Поступления от аренды недвижимости
A22: 3.5 | B22: Поступления от аренды других основных средств
A23: 3.6 | B23: Прочие поступления по текущей деятельности
A24: 4 | B24: Выплаты по текущей деятельности (стр. 4.1 + стр. 4.2 + стр. 4.3 + стр. 4.4 + стр. 4.5)
A25: 4.1 | B25: Выплаты за материальные ресурсы (стр. 4.1.1 + 4.1.2 + 4.1.3 + 4.1.4 + 4.1.5 + 4.1.6)
A26: 4.1.1 | B26: Выплаты за материалы (стр. 4.1.1.1 + стр. 4.1.1.2)
A27: 4.1.1.1 | B27: Выплаты за материалы на производство продукции (работ, услуг)
A28: 4.1.1.2 | B28: Выплаты за прочие материалы
A29: 4.1.2 | B29: Выплаты за покупные комплектующие изделия
A30: 4.1.3 | B30: Выплаты за полуфабрикаты
A31: 4.1.4 | B31: Выплаты за спецоборудование для экспериментальных работ
A32: 4.1.5 | B32: Выплаты за инвентарь и хозяйственные принадлежности
A33: 4.1.6 | B33: Выплаты за топливо и энергию
A34: 4.2 | B34: Оплата труда (стр. 4.2.1 + 4.2.2)
A35: 4.2.1 | B35: Оплата труда постоянного персонала
A36: 4.2.2 | B36: Оплата труда временно привлеченного персонала
... A51: 4.5 | B51: Прочие выплаты по текущей деятельности
A52: 5 | B52: Сальдо по текущей деятельности (стр. 3 - стр. 4)
A53: 6 | B53: Инвестиционная деятельность | C53: Х | D53: Х
A54: 7 | B54: Поступления от инвестиционной деятельности (стр. 7.1 + стр. 7.2 + стр. 7.3 + стр. 7.4 + стр. 7.5 + стр. 7.6 + стр. 7.7)
A55: 7.1 | B55: Поступления от реализации недвижимости и других основных средств, нематериальных активов
A56: 7.2 | B56: Возврат долгосрочных займов, поступления от реализации ценных бумаг, долей участия, других долгосрочных финансовых вложений (стр. 7.2.1 + стр. 7.2.2)
...

Sheet VII-3
Q1: Таблица VII/3
B2: Сокращенное название организации
A4: Сведения о начисленных и уплаченных налогах, сборах и страховых взносах
Q5: (тыс. руб.)
A6: № п/п | B6: Наименование налогов, сборов и страховых взносов | C6: Задолженность по налогам, сборам и страховым взносам на начало отчетного года | G6: Начисленные за период налоги, сборы и страховые взносы | J6: Уплаченные в отчетном периоде налоги, сборы и страховые взносы | N6: Задолженность по налогам, сборам и страховым взносам на конец отчетного года
C7: всего | D7: в том числе | G7: всего | H7: в том числе: | J7: всего | K7: в том числе | N7: всего | O7: в том числе
D8: федеральный бюджет | E8: региональный бюджет | F8: местный бюджет | H8: налоги, сборы, страховые взносы | I8: штрафы и пени | K8: федеральный бюджет | L8: региональный бюджет | M8: местный бюджет | O8: федеральный бюджет | P8: региональный бюджет | Q8: местный бюджет
A9: 1 | B9: 2 | C9: 3 | D9: 4 | E9: 5 | F9: 6 | G9: 7 | H9: 8 | I9: 9 | J9: 10 | K9: 11 | L9: 12 | M9: 13 | N9: 14 | O9: 15 | P9: 16 | Q9: 17
K15: Подпись
L16: должность, Ф.И.О. исполнителя и его контактный телефон

Sheet VII-4
J1: Таблица VII/4
A3: Сокращенное название организации
A5: Информация о долгосрочных финансовых вложениях в другие организации
A7: № п/п | B7: Полное и сокращенное наименование организации | C7: Юридичес- кий и почто- вый адреса организации, телефон | D7: Ф.И.О. руководи- теля | E7: Год приобре-тения акций (доли) | F7: Учреждение организации | I7: Текущая сфера деятель- ности | J7: Участие организации в основной деятельности предприятия | K7: Уставный капитал организа- ции, тыс.руб. | L7: Доля предприятия в уставном капитале организации | N7: Выручка организации, тыс. руб. | O7: Чистая прибыль организации, тыс. руб. | P7: Дивиденды, тыс. руб.
F8: год | G8: форма взноса | H8: сфера деятельности | L8: тыс.руб. | M8: % | P8: отчетный год | Q8: следующий год
A9: 1 | B9: 2 | C9: 3 | D9: 4 | E9: 5 | F9: 6 | G9: 7 | H9: 8 | I9: 9 | J9: 10 | K9: 11 | L9: 12 | M9: 13 | N9: 14 | O9: 15 | P9: 16 | Q9: 17
A12: ИТОГО:
M14: Подпись
N15: должность, Ф.И.О. исполнителя и его контактный телефон

Sheet VII-5
H1: Таблица VII/5
B2: Сокращенное название организации
A4: Сведения о дебиторской задолженности
H5: (тыс.руб. без учета НДС)
A6: Код строки | B6: Наименование | C6: На конец отчетного года | H6: На конец предыдущего отчетному года
C7: всего | D7: краткосро- чная | E7: долгосроч- ная | F7: просроче- нная | G7: нереальная к взысканию просроченная задолженность
A8: 1 | B8: 2 | C8: 3 | D8: 4 | E8: 5 | F8: 6 | G8: 7 | H8: 8
A9: 100 | B9: Дебиторская задолженность, всего:
A10: 200 | B10: Задолженность покупателей и заказчиков, в том числе:
A11: 201 | B11: авансы выданные
A12: 202 | B12: государственных заказчиков по заключенным государственным контрактам
A13: 203 | B13: по расчетам с дочерними и зависимыми обществами по всем видам операций
A14: 204 | B14: по коммунальным платежам, платежам за тепло- и энергообеспече-ние и т.п.
A15: 205 | B15: по штрафам, пеням и неустойкам, признанным или по которым получены решения суда
A16: 206 | B16: прочее
A17: 300 | B17: Задолженность работников организации
A18: 400 | B18: Задолженность по налогам и сборам всего, в том числе:
A19: 401 | B19: федеральный бюджет
A20: 402 | B20: бюджет субъекта РФ
... A29: 800 | B29: Справочно: Резервы по сомнительным долгам
D31: Подпись
E32: должность, Ф.И.О. исполнителя и его контактный телефон

Sheet VII-6
G1: Таблица VII/6
B2: Сокращенное название организации
A4: Сведения о кредиторской задолженности
G6: (тыс.руб. без учета НДС)
A7: Код строки | B7: Наименование | C7: На конец отчетного года | G7: На конец предыдущего года
C8: всего | D8: краткосрочная | E8: долгосрочная | F8: просроченная
A9: 1 | B9: 2 | C9: 3 | D9: 4 | E9: 5 | F9: 6 | G9: 7
A10: 100 | B10: Кредиторская задолженность всего, в том числе:
A11: 110 | B11: Задолженность поставщикам и подрядчикам всего, в том числе:
A12: 111 | B12: авансы полученные
A13: 112 | B13: государственным заказчикам по заключенным государственным контрактам
